<?xml version="1.0" ?>
<sdf version="1.5">
  <model name="pioneer3at">
    <pose>0 0 0.180 0 0 0</pose>
    <static>false</static>
    <link name="chassis">
      <inertial>
        <mass>14.0</mass>
        <inertia>
          <ixx>0.147116667</ixx>
          <ixy>0.0</ixy>
          <ixz>0.0</ixz>
          <iyy>0.334951167</iyy>
          <iyz>0.0</iyz>
          <izz>0.3978345</izz>
        </inertia>
      </inertial>
      <collision name="collision">
        <geometry>
          <box>
            <size>0.501 0.300 0.19</size>
          </box>
        </geometry>
      </collision>
      <visual name="visual">
        <geometry>
          <mesh>
            <uri>model://pioneer3at/meshes/chassis.dae</uri>
          </mesh>
        </geometry>
      </visual>
    </link>
    <link name="right_front_wheel">
      <pose>0.125 -0.201 -0.06 1.5707 0 0</pose>

      <inertial>
        <mass>1.5</mass>
        <inertia>
          <ixx>0.005240625</ixx>
          <iyy>0.005240625</iyy>
          <izz>0.009075</izz>
          <ixy>0</ixy>
          <ixz>0</ixz>
          <iyz>0</iyz>
        </inertia>
      </inertial>

      <collision name="collision">
        <geometry>
          <cylinder>
            <radius>0.110</radius>
            <length>0.075</length>
          </cylinder>
        </geometry>
        <surface>
          <friction>
            <ode>
              <mu>1</mu>
              <mu2>1</mu2>
              <slip1>0.5</slip1>
              <slip2>0</slip2>
            </ode>
          </friction>
        </surface>
      </collision>
      <visual name="visual">
        <geometry>
          <mesh>
            <uri>model://pioneer3at/meshes/wheel.dae</uri>
          </mesh>
        </geometry>
      </visual>
    </link>
    <link name="left_front_wheel">
      <pose>0.125 0.201 -0.06 1.5707 0 0</pose>

      <inertial>
        <mass>1.5</mass>
        <inertia>
          <ixx>0.005240625</ixx>
          <iyy>0.005240625</iyy>
          <izz>0.009075</izz>
          <ixy>0</ixy>
          <ixz>0</ixz>
          <iyz>0</iyz>
        </inertia>
      </inertial>

      <collision name="collision">
        <geometry>
          <cylinder>
            <radius>0.110</radius>
            <length>0.075</length>
          </cylinder>
        </geometry>
        <surface>
          <friction>
            <ode>
              <mu>1</mu>
              <mu2>1</mu2>
              <slip1>0.5</slip1>
              <slip2>0</slip2>
            </ode>
          </friction>
        </surface>
      </collision>
      <visual name="visual">
        <geometry>
          <mesh>
            <uri>model://pioneer3at/meshes/wheel.dae</uri>
          </mesh>
        </geometry>
      </visual>
    </link>
    <link name="right_rear_wheel">
      <pose>-0.125 -0.201 -0.06 1.5707 0 0</pose>

      <inertial>
        <mass>1.5</mass>
        <inertia>
          <ixx>0.005240625</ixx>
          <iyy>0.005240625</iyy>
          <izz>0.009075</izz>
          <ixy>0</ixy>
          <ixz>0</ixz>
          <iyz>0</iyz>
        </inertia>
      </inertial>

      <collision name="collision">
        <geometry>
          <cylinder>
            <radius>0.110</radius>
            <length>0.075</length>
          </cylinder>
        </geometry>
        <surface>
          <friction>
            <ode>
              <mu>1</mu>
              <mu2>1</mu2>
              <slip1>0.5</slip1>
              <slip2>0</slip2>
            </ode>
          </friction>
        </surface>
      </collision>
      <visual name="visual">
        <geometry>
          <mesh>
            <uri>model://pioneer3at/meshes/wheel.dae</uri>
          </mesh>
        </geometry>
      </visual>
    </link>
    <link name="left_rear_wheel">
      <pose>-0.125 0.201 -0.06 1.5707 0 0</pose>

      <inertial>
        <mass>1.5</mass>
        <inertia>
          <ixx>0.005240625</ixx>
          <iyy>0.005240625</iyy>
          <izz>0.009075</izz>
          <ixy>0</ixy>
          <ixz>0</ixz>
          <iyz>0</iyz>
        </inertia>
      </inertial>

      <collision name="collision">
        <geometry>
          <cylinder>
            <radius>0.110</radius>
            <length>0.075</length>
          </cylinder>
        </geometry>
        <surface>
          <friction>
            <ode>
              <mu>1</mu>
              <mu2>1</mu2>
              <slip1>0.5</slip1>
              <slip2>0</slip2>
            </ode>
          </friction>
        </surface>
      </collision>
      <visual name="visual">
        <geometry>
          <mesh>
            <uri>model://pioneer3at/meshes/wheel.dae</uri>
          </mesh>
        </geometry>
      </visual>
    </link>
    <joint type="revolute" name="right_front">
      <pose>0 0 0 0 0 0</pose>
      <child>right_front_wheel</child>
      <parent>chassis</parent>
      <axis>
        <xyz>0 1 0</xyz>
        <use_parent_model_frame>true</use_parent_model_frame>
      </axis>
    </joint>
    <joint type="revolute" name="right_rear">
      <pose>0 0 0 0 0 0</pose>
      <child>right_rear_wheel</child>
      <parent>chassis</parent>
      <axis>
        <xyz>0 1 0</xyz>
        <use_parent_model_frame>true</use_parent_model_frame>
      </axis>
    </joint>
    <joint type="revolute" name="left_front">
      <pose>0 0 0 0 0 0</pose>
      <child>left_front_wheel</child>
      <parent>chassis</parent>
      <axis>
        <xyz>0 1 0</xyz>
        <use_parent_model_frame>true</use_parent_model_frame>
      </axis>
    </joint>
    <joint type="revolute" name="left_rear">
      <pose>0 0 0 0 0 0</pose>
      <child>left_rear_wheel</child>
      <parent>chassis</parent>
      <axis>
        <xyz>0 1 0</xyz>
        <use_parent_model_frame>true</use_parent_model_frame>
      </axis>
    </joint>
    <plugin name="SkidSteerDrivePlugin" filename="libSkidSteerDrivePlugin.so">
      <right_front>right_front</right_front>
      <right_rear>right_rear</right_rear>
      <left_front>left_front</left_front>
      <left_rear>left_rear</left_rear>
      <MaxForce>5.0</MaxForce>
    </plugin>


    <joint name="base_laser_front_hokuyo_urg04_laser_joint" type="revolute">
      <pose>0 0 0 0 0 0</pose>
      <parent>chassis</parent>
      <child>base_laser_front_link</child>
      <axis>
        <dynamics>
          <damping>0</damping>
          <friction>0</friction>
        </dynamics>
        <limit><lower>0</lower><upper>0</upper><effort>0</effort><velocity>0</velocity></limit>
        <xyz>0 0 1</xyz>
      </axis>
    </joint>

    <link name="base_laser_front_link">
      <pose>0.300000 0 -0.030000 0 0 0</pose>
      <inertial>
        <pose>0 0 0 0 0 0</pose>
        <inertia>
          <ixx>0.100000</ixx>
          <ixy>0</ixy>
          <ixz>0</ixz>
          <iyy>0.100000</iyy>
          <iyz>0</iyz>
          <izz>0.100000</izz>
        </inertia>
        <mass>0.160000</mass>
      </inertial>
      <collision name="base_laser_front_link_geom">
        <pose>0 0 0 0 0 0</pose>
        <geometry>
          <mesh>
            <uri>model://hokuyo/meshes/hokuyo_convex.stl</uri>
          </mesh>
        </geometry>
        <surface>
          <friction>
            <ode>
              <mu>0</mu>
              <mu2>0</mu2>
              <fdir1>0 0 0</fdir1>
              <slip1>0</slip1>
              <slip2>0</slip2>
            </ode>
          </friction>
          <bounce>
            <restitution_coefficient>0</restitution_coefficient>
            <threshold>0</threshold>
          </bounce>
          <contact>
            <ode>
              <soft_cfm>0</soft_cfm>
              <soft_erp>0.200000</soft_erp>
              <kp>10000000000000.000000</kp>
              <kd>100000000000.000000</kd>
              <max_vel>-1</max_vel>
              <min_depth>0</min_depth>
            </ode>
          </contact>
        </surface>
        <laser_retro>0</laser_retro>
      </collision>
      <visual name="base_laser_front_link_geom_visual">
        <pose>0 0 0 0 0 0</pose>
        <geometry>
          <mesh>
            <uri>model://hokuyo/meshes/hokuyo.dae</uri>
          </mesh>
        </geometry>
      </visual>
      <sensor name="base_laser_front" type="ray">
        <pose>0 0 0 0 0 0</pose>
        <ray>
          <scan>
            <horizontal>
              <samples>640</samples>
              <resolution>1</resolution>
              <min_angle>-1.570000</min_angle>
              <max_angle>1.570000</max_angle>
            </horizontal>
          </scan>
          <range>
            <min>0.050000</min>
            <max>5.600000</max>
            <resolution>0.360000</resolution>
          </range>
        </ray>z

	<plugin name='laser_controller' filename='libgazebo_ros_laser.so'>
          <gaussianNoise>0.005</gaussianNoise>
          <alwaysOn>1</alwaysOn>
          <updateRate>20</updateRate>
          <topicName>pioneer3at/scan</topicName>
          <frameName>laser</frameName>
        </plugin>

	<update_rate>20</update_rate>
	<visualize>0</visualize>
      </sensor>
      <gravity>1</gravity>
      <self_collide>0</self_collide>
      <kinematic>0</kinematic>
    </link>

    <!--    
      <include>
        <uri>model://hokuyo</uri>
        <pose>0.2 0 0.13 0 0 0</pose>
      </include>
      <joint name="hokuyo_joint" type="revolute">
        <child>hokuyo::link</child>
        <parent>chassis</parent>
        <axis>
          <xyz>0 0 1</xyz>
          <limit>
            <upper>0</upper>
            <lower>0</lower>
          </limit>
        </axis>
      </joint>
    -->
  </model>
</sdf>
